<?xml version='1.0' encoding='UTF-8'?>
<robot name="fetch">
  <link name="base_link">
    <inertial>
      <origin xyz="-0.0036 0.0 0.0014" rpy="1.56 0.0 0.0"/>
      <mass value="70.1294"/>
      <inertia ixx="1.225" ixy="0.0099" ixz="0.0062" iyy="1.2853" iyz="-0.0034" izz="0.987"/>
    </inertial>
    <visual>
      <geometry>
        <mesh filename="../meshes/base_link.dae"/>
      </geometry>
      <material name="mat0"/>
      <origin xyz="0.0 0.0 0.0" rpy="0.0 0.0 0.0"/>
    </visual>
    <collision>
      <geometry>
        <cylinder radius="0.285" length="0.32"/>
      </geometry>
      <origin xyz="0.0 0.0 0.2" rpy="0.0 0.0 0.0"/>
    </collision>
    <collision>
      <geometry>
        <cylinder radius="0.03" length="0.03"/>
      </geometry>
      <origin xyz="0.1655 0.12 0.0325" rpy="1.56 0.0 0.0"/>
    </collision>
    <collision>
      <geometry>
        <cylinder radius="0.03" length="0.03"/>
      </geometry>
      <origin xyz="0.1655 -0.12 0.0325" rpy="1.56 0.0 0.0"/>
    </collision>
    <collision>
      <geometry>
        <cylinder radius="0.03" length="0.03"/>
      </geometry>
      <origin xyz="-0.21 0.12 0.0325" rpy="1.56 0.0 0.0"/>
    </collision>
    <collision>
      <geometry>
        <cylinder radius="0.03" length="0.03"/>
      </geometry>
      <origin xyz="-0.21 -0.12 0.0325" rpy="1.56 0.0 0.0"/>
    </collision>
  </link>
  <link name="r_wheel_link">
    <inertial>
      <origin xyz="0.0 0.0 0.0" rpy="0.0 0.0 0.0"/>
      <mass value="4.3542"/>
      <inertia ixx="0.0045" ixy="0.0" ixz="0.0" iyy="0.005" iyz="0.0" izz="0.0045"/>
    </inertial>
    <visual>
      <geometry>
        <mesh filename="../meshes/r_wheel_link.STL"/>
      </geometry>
      <material name="mat1"/>
      <origin xyz="0.0 0.0 0.0" rpy="0.0 0.0 0.0"/>
    </visual>
    <collision>
      <geometry>
        <cylinder radius="0.06" length="0.06"/>
      </geometry>
      <origin xyz="0.0 0.0 0.0" rpy="1.56 0.0 0.0"/>
    </collision>
  </link>
  <link name="l_wheel_link">
    <inertial>
      <origin xyz="0.0 0.0 0.0" rpy="0.0 0.0 0.0"/>
      <mass value="4.3542"/>
      <inertia ixx="0.0045" ixy="0.0" ixz="0.0" iyy="0.005" iyz="0.0" izz="0.0045"/>
    </inertial>
    <visual>
      <geometry>
        <mesh filename="../meshes/l_wheel_link.STL"/>
      </geometry>
      <material name="mat2"/>
      <origin xyz="0.0 0.0 0.0" rpy="0.0 0.0 0.0"/>
    </visual>
    <collision>
      <geometry>
        <cylinder radius="0.06" length="0.06"/>
      </geometry>
      <origin xyz="0.0 0.0 0.0" rpy="1.56 0.0 0.0"/>
    </collision>
  </link>
  <link name="torso_lift_link">
    <inertial>
      <origin xyz="-0.0013 -0.0009 0.2935" rpy="0.0 0.0 0.0"/>
      <mass value="10.7796"/>
      <inertia ixx="0.3354" ixy="0.0" ixz="-0.0162" iyy="0.3354" iyz="-0.0006" izz="0.0954"/>
    </inertial>
    <visual>
      <geometry>
        <mesh filename="../meshes/torso_lift_link.dae"/>
      </geometry>
      <material name="math3"/>
      <origin xyz="0.0 0.0 0.0" rpy="0.0 0.0 0.0"/>
    </visual>
    <collision>
      <geometry>
        <box size="0.246 0.347 0.573"/>
      </geometry>
      <origin xyz="-0.06 0.0 0.3" rpy="0.0 0.0 0.0"/>
    </collision>
  </link>
  <link name="head_pan_link">
    <inertial>
      <origin xyz="0.0321 0.0161 0.039" rpy="0.0 0.0 0.0"/>
      <mass value="2.2556"/>
      <inertia ixx="0.0129" ixy="0.0002" ixz="0.0007" iyy="0.0095" iyz="-0.0" izz="0.0184"/>
    </inertial>
    <visual>
      <geometry>
        <mesh filename="../meshes/head_pan_link.dae"/>
      </geometry>
      <material name="math4"/>
      <origin xyz="0.0 0.0 0.0" rpy="0.0 0.0 0.0"/>
    </visual>
    <collision>
      <geometry>
        <box size="0.275 0.3   0.11 "/>
      </geometry>
      <origin xyz="0.065 0.0 0.054" rpy="0.0 0.0 0.0"/>
    </collision>
  </link>
  <link name="head_tilt_link">
    <inertial>
      <origin xyz="0.0081 0.0025 0.0113" rpy="0.0 0.0 0.0"/>
      <mass value="0.9087"/>
      <inertia ixx="0.0061" ixy="-0.0" ixz="0.0002" iyy="0.0014" iyz="-0.0001" izz="0.0061"/>
    </inertial>
    <visual>
      <geometry>
        <mesh filename="../meshes/head_tilt_link.dae"/>
      </geometry>
      <material name="5"/>
      <origin xyz="0.0 0.0 0.0" rpy="0.0 0.0 0.0"/>
    </visual>
  </link>
  <link name="shoulder_pan_link">
    <inertial>
      <origin xyz="0.0927 -0.0056 0.0564" rpy="0.0 0.0 0.0"/>
      <mass value="2.5587"/>
      <inertia ixx="0.0043" ixy="-0.0001" ixz="0.001" iyy="0.0087" iyz="-0.0001" izz="0.0087"/>
    </inertial>
    <visual>
      <geometry>
        <mesh filename="../meshes/shoulder_pan_link.dae"/>
      </geometry>
      <material name="6"/>
      <origin xyz="0.0 0.0 0.0" rpy="0.0 0.0 0.0"/>
    </visual>
  </link>
  <link name="shoulder_lift_link">
    <inertial>
      <origin xyz="0.1432 0.0072 -0.0001" rpy="0.0 0.0 0.0"/>
      <mass value="2.6615"/>
      <inertia ixx="0.0028" ixy="-0.0021" ixz="-0.0" iyy="0.0111" iyz="-0.0" izz="0.0112"/>
    </inertial>
    <visual>
      <geometry>
        <mesh filename="../meshes/shoulder_lift_link.dae"/>
      </geometry>
      <material name="7"/>
      <origin xyz="0.0 0.0 0.0" rpy="0.0 0.0 0.0"/>
    </visual>
    <collision>
      <geometry>
        <mesh filename="../meshes/shoulder_lift_link_collision.obj"/>
      </geometry>
      <origin xyz="0.0 0.0 0.0" rpy="0.0 0.0 0.0"/>
    </collision>
  </link>
  <link name="upperarm_roll_link">
    <inertial>
      <origin xyz="0.1165 0.0014 0.0" rpy="0.0 0.0 0.0"/>
      <mass value="2.3311"/>
      <inertia ixx="0.0019" ixy="-0.0001" ixz="0.0" iyy="0.0045" iyz="0.0" izz="0.0047"/>
    </inertial>
    <visual>
      <geometry>
        <mesh filename="../meshes/upperarm_roll_link.dae"/>
      </geometry>
      <material name="8"/>
      <origin xyz="0.0 0.0 0.0" rpy="0.0 0.0 0.0"/>
    </visual>
    <collision>
      <geometry>
        <mesh filename="../meshes/upperarm_roll_link_collision.obj"/>
      </geometry>
      <origin xyz="0.0 0.0 0.0" rpy="0.0 0.0 0.0"/>
    </collision>
  </link>
  <link name="elbow_flex_link">
    <inertial>
      <origin xyz="0.1279 0.0073 0.0" rpy="0.0 0.0 0.0"/>
      <mass value="2.1299"/>
      <inertia ixx="0.0024" ixy="-0.0016" ixz="0.0" iyy="0.0082" iyz="-0.0" izz="0.0084"/>
    </inertial>
    <visual>
      <geometry>
        <mesh filename="../meshes/elbow_flex_link.dae"/>
      </geometry>
      <material name="9"/>
      <origin xyz="0.0 0.0 0.0" rpy="0.0 0.0 0.0"/>
    </visual>
    <collision>
      <geometry>
        <mesh filename="../meshes/elbow_flex_link_collision.obj"/>
      </geometry>
      <origin xyz="0.0 0.0 0.0" rpy="0.0 0.0 0.0"/>
    </collision>
  </link>
  <link name="forearm_roll_link">
    <inertial>
      <origin xyz="0.1097 -0.0266 0.0" rpy="0.0 0.0 0.0"/>
      <mass value="1.6563"/>
      <inertia ixx="0.0016" ixy="-0.0003" ixz="0.0" iyy="0.003" iyz="-0.0" izz="0.0035"/>
    </inertial>
    <visual>
      <geometry>
        <mesh filename="../meshes/forearm_roll_link.dae"/>
      </geometry>
      <material name="10"/>
      <origin xyz="0.0 0.0 0.0" rpy="0.0 0.0 0.0"/>
    </visual>
    <collision>
      <geometry>
        <mesh filename="../meshes/forearm_roll_link_collision.obj"/>
      </geometry>
      <origin xyz="0.0 0.0 0.0" rpy="0.0 0.0 0.0"/>
    </collision>
  </link>
  <link name="wrist_flex_link">
    <inertial>
      <origin xyz="0.0882 0.0009 -0.0001" rpy="0.0 0.0 0.0"/>
      <mass value="1.725"/>
      <inertia ixx="0.0018" ixy="-0.0001" ixz="-0.0" iyy="0.0042" iyz="0.0" izz="0.0042"/>
    </inertial>
    <visual>
      <geometry>
        <mesh filename="../meshes/wrist_flex_link.dae"/>
      </geometry>
      <material name="11"/>
      <origin xyz="0.0 0.0 0.0" rpy="0.0 0.0 0.0"/>
    </visual>
    <collision>
      <geometry>
        <mesh filename="../meshes/wrist_flex_link_collision.obj"/>
      </geometry>
      <origin xyz="0.0 0.0 0.0" rpy="0.0 0.0 0.0"/>
    </collision>
  </link>
  <link name="wrist_roll_link">
    <inertial>
      <origin xyz="0.0095 0.0004 -0.0002" rpy="0.0 0.0 0.0"/>
      <mass value="0.1354"/>
      <inertia ixx="0.0001" ixy="0.0" ixz="0.0" iyy="0.0001" iyz="0.0" izz="0.0001"/>
    </inertial>
    <visual>
      <geometry>
        <mesh filename="../meshes/wrist_roll_link.dae"/>
      </geometry>
      <material name="12"/>
      <origin xyz="0.0 0.0 0.0" rpy="0.0 0.0 0.0"/>
    </visual>
    <collision>
      <geometry>
        <mesh filename="../meshes/wrist_roll_link_collision.obj"/>
      </geometry>
      <origin xyz="0.0 0.0 0.0" rpy="0.0 0.0 0.0"/>
    </collision>
  </link>
  <link name="gripper_link">
    <inertial>
      <origin xyz="-0.09 -0.0001 -0.0017" rpy="0.0 0.0 0.0"/>
      <mass value="1.5175"/>
      <inertia ixx="0.0013" ixy="-0.0" ixz="0.0" iyy="0.0019" iyz="-0.0" izz="0.0024"/>
    </inertial>
    <visual>
      <geometry>
        <mesh filename="../meshes/gripper_link.dae"/>
      </geometry>
      <origin xyz="0.0 0.0 0.0" rpy="0.0 0.0 0.0"/>
    </visual>
    <collision>
      <geometry>
        <mesh filename="../meshes/gripper_link_collision.obj"/>
      </geometry>
      <origin xyz="0.0 0.0 0.0" rpy="0.0 0.0 0.0"/>
    </collision>
  </link>
  <link name="r_gripper_finger_link">
    <inertial>
      <origin xyz="-0.01 0.0 0.0" rpy="0.0 0.0 0.0"/>
      <mass value="0.0798"/>
      <inertia ixx="0.002" ixy="0.0" ixz="0.0" iyy="0.0" iyz="0.0" izz="0.0"/>
    </inertial>
    <visual>
      <geometry>
        <mesh filename="../meshes/r_gripper_finger_link.STL"/>
      </geometry>
      <material name="13"/>
      <origin xyz="0.0 0.101425 0.0" rpy="0.0 0.0 0.0"/>
    </visual>
    <collision>
      <geometry>
        <box size="0.06  0.015 0.027"/>
      </geometry>
      <origin xyz="0.0 -0.0075 0.0" rpy="0.0 0.0 0.0"/>
    </collision>
  </link>
  <link name="l_gripper_finger_link">
    <inertial>
      <origin xyz="-0.01 0.0 0.0" rpy="0.0 0.0 0.0"/>
      <mass value="0.0798"/>
      <inertia ixx="0.002" ixy="0.0" ixz="0.0" iyy="0.0" iyz="0.0" izz="0.0"/>
    </inertial>
    <visual>
      <geometry>
        <mesh filename="../meshes/l_gripper_finger_link.STL"/>
      </geometry>
      <material name="14"/>
      <origin xyz="0.0 -0.101425 0.0" rpy="0.0 0.0 0.0"/>
    </visual>
    <collision>
      <geometry>
        <box size="0.06  0.015 0.027"/>
      </geometry>
      <origin xyz="0.0 0.0075 0.0" rpy="0.0 0.0 0.0"/>
    </collision>
  </link>
  <link name="bellows_link">
    <inertial>
      <origin xyz="0.0191320000286228 -1.67219873481315e-16 -0.134861625443387" rpy="0.0 0.0 0.0"/>
      <mass value="0.169374038216602"/>
      <inertia ixx="0.00331159128762117" ixy="-8.9230964321455e-18" ixz="-5.38622201018293e-08" iyy="0.00174447292786627" iyz="-8.06964979976371e-17" izz="0.00169417568121457"/>
    </inertial>
    <visual>
      <geometry>
        <mesh filename="../meshes/bellows_link.STL"/>
      </geometry>
      <material name="15"/>
      <origin xyz="0.0 0.0 0.0" rpy="0.0 0.0 0.0"/>
    </visual>
    <collision>
      <geometry>
        <mesh filename="../meshes/bellows_link_collision.obj"/>
      </geometry>
      <origin xyz="0.0 0.0 0.0" rpy="0.0 0.0 0.0"/>
    </collision>
  </link>
  <link name="bellows_link2">
    <inertial>
      <origin xyz="0.0191320000286228 -1.67219873481315e-16 -0.134861625443387" rpy="0.0 0.0 0.0"/>
      <mass value="0.169374038216602"/>
      <inertia ixx="0.00331159128762117" ixy="-8.9230964321455e-18" ixz="-5.38622201018293e-08" iyy="0.00174447292786627" iyz="-8.06964979976371e-17" izz="0.00169417568121457"/>
    </inertial>
    <visual>
      <geometry>
        <mesh filename="../meshes/bellows_link.STL"/>
      </geometry>
      <material name="16"/>
      <origin xyz="0.0 0.0 0.0" rpy="0.0 0.0 0.0"/>
    </visual>
    <collision>
      <geometry>
        <mesh filename="../meshes/bellows_link_collision.obj"/>
      </geometry>
      <origin xyz="0.0 0.0 0.0" rpy="0.0 0.0 0.0"/>
    </collision>
  </link>
  <link name="estop_link">
    <inertial>
      <origin xyz="0.002434512737072 -0.00330608315239905 0.00665139196650039" rpy="0.0 0.0 0.0"/>
      <mass value="0.00196130439134723"/>
      <inertia ixx="3.02810026604417e-07" ixy="-1.5862023118056e-08" ixz="3.16561396557437e-08" iyy="2.93322917127605e-07" iyz="-4.28833522751273e-08" izz="2.28513272627183e-07"/>
    </inertial>
    <visual>
      <geometry>
        <mesh filename="../meshes/estop_link.dae"/>
      </geometry>
      <material name="17"/>
      <origin xyz="0.0 0.0 0.0" rpy="0.0 0.0 0.0"/>
    </visual>
  </link>
  <link name="laser_link">
    <inertial>
      <origin xyz="-0.0306228970175641 0.0007091682908278 0.0551974119471302" rpy="0.0 0.0 0.0"/>
      <mass value="0.00833634573995571"/>
      <inertia ixx="1.01866461240801e-06" ixy="-5.88447626567756e-08" ixz="7.83857244757914e-08" iyy="5.10039589974707e-07" iyz="-7.12664289617235e-09" izz="1.28270671527309e-06"/>
    </inertial>
    <visual>
      <geometry>
        <mesh filename="../meshes/laser_link.STL"/>
      </geometry>
      <material name="18"/>
      <origin xyz="0.0 0.0 0.0" rpy="0.0 0.0 0.0"/>
    </visual>
  </link>
  <link name="torso_fixed_link">
    <inertial>
      <origin xyz="-0.0722 0.0057 0.2656" rpy="0.0 0.0 0.0"/>
      <mass value="130.2775"/>
      <inertia ixx="0.3861" ixy="0.0015" ixz="-0.0102" iyy="0.3388" iyz="0.0117" izz="0.1018"/>
    </inertial>
    <visual>
      <geometry>
        <mesh filename="../meshes/torso_fixed_link.dae"/>
      </geometry>
      <material name=""/>
      <origin xyz="0.0 0.0 0.0" rpy="0.0 0.0 0.0"/>
    </visual>
  </link>
  <link name="head_camera_link">
    <inertial>
      <origin xyz="0.0 0.0 0.0" rpy="0.0 -0.0 0.0"/>
      <mass value="1.0"/>
      <inertia ixx="1.0" ixy="0.0" ixz="0.0" iyy="1.0" iyz="0.0" izz="1.0"/>
    </inertial>
  </link>
  <link name="head_camera_rgb_frame">
    <inertial>
      <origin xyz="0.0 0.0 0.0" rpy="0.0 -0.0 0.0"/>
      <mass value="1.0"/>
      <inertia ixx="1.0" ixy="0.0" ixz="0.0" iyy="1.0" iyz="0.0" izz="1.0"/>
    </inertial>
  </link>
  <link name="head_camera_rgb_optical_frame">
    <inertial>
      <origin xyz="0.0 0.0 0.0" rpy="0.0 -0.0 0.0"/>
      <mass value="1.0"/>
      <inertia ixx="1.0" ixy="0.0" ixz="0.0" iyy="1.0" iyz="0.0" izz="1.0"/>
    </inertial>
  </link>
  <link name="head_camera_depth_frame">
    <inertial>
      <origin xyz="0.0 0.0 0.0" rpy="0.0 -0.0 0.0"/>
      <mass value="1.0"/>
      <inertia ixx="1.0" ixy="0.0" ixz="0.0" iyy="1.0" iyz="0.0" izz="1.0"/>
    </inertial>
  </link>
  <link name="head_camera_depth_optical_frame">
    <inertial>
      <origin xyz="0.0 0.0 0.0" rpy="0.0 -0.0 0.0"/>
      <mass value="1.0"/>
      <inertia ixx="1.0" ixy="0.0" ixz="0.0" iyy="1.0" iyz="0.0" izz="1.0"/>
    </inertial>
  </link>
  <link name="articulated_agent_arm">
    <inertial>
      <origin xyz="0.0 0.0 0.0" rpy="0.0 -0.0 0.0"/>
      <mass value="1.0"/>
      <inertia ixx="1.0" ixy="0.0" ixz="0.0" iyy="1.0" iyz="0.0" izz="1.0"/>
    </inertial>
  </link>
  <joint name="r_wheel_joint" type="continuous">
    <limit effort="8.85" velocity="17.4"/>
    <parent link="base_link"/>
    <child link="r_wheel_link"/>
    <axis xyz="0. 1. 0."/>
    <origin xyz="0.0012914 -0.18738 0.055325" rpy="-6.123e-17 0.0 0.0"/>
  </joint>
  <joint name="l_wheel_joint" type="continuous">
    <limit effort="8.85" velocity="17.4"/>
    <parent link="base_link"/>
    <child link="l_wheel_link"/>
    <axis xyz="0. 1. 0."/>
    <origin xyz="0.0012914 0.18738 0.055325" rpy="-6.123e-17 0.0 0.0"/>
  </joint>
  <joint name="torso_lift_joint" type="prismatic">
    <dynamics damping="100.0"/>
    <limit effort="450.0" velocity="0.1" lower="0.0" upper="0.38615"/>
    <parent link="base_link"/>
    <child link="torso_lift_link"/>
    <axis xyz="0. 0. 1."/>
    <origin xyz="-0.086875 0.0 0.37743" rpy="-6.123e-17 0.0 0.0"/>
  </joint>
  <joint name="head_pan_joint" type="revolute">
    <limit effort="0.32" velocity="1.57" lower="-1.57" upper="1.57"/>
    <parent link="torso_lift_link"/>
    <child link="head_pan_link"/>
    <axis xyz="0. 0. 1."/>
    <origin xyz="0.053125 0.0 0.603001417713939" rpy="0.0 0.0 0.0"/>
  </joint>
  <joint name="head_tilt_joint" type="revolute">
    <limit effort="0.68" velocity="1.57" lower="-0.76" upper="1.45"/>
    <parent link="head_pan_link"/>
    <child link="head_tilt_link"/>
    <axis xyz="0. 1. 0."/>
    <origin xyz="0.14253 0.0 0.057999" rpy="0.0 0.0 0.0"/>
  </joint>
  <joint name="shoulder_pan_joint" type="revolute">
    <dynamics damping="1.0"/>
    <limit effort="33.82" velocity="1.256" lower="-1.6056" upper="1.6056"/>
    <parent link="torso_lift_link"/>
    <child link="shoulder_pan_link"/>
    <axis xyz="0. 0. 1."/>
    <origin xyz="0.119525 0.0 0.34858" rpy="0.0 0.0 0.0"/>
  </joint>
  <joint name="shoulder_lift_joint" type="revolute">
    <dynamics damping="1.0"/>
    <limit effort="131.76" velocity="1.454" lower="-1.221" upper="1.518"/>
    <parent link="shoulder_pan_link"/>
    <child link="shoulder_lift_link"/>
    <axis xyz="0. 1. 0."/>
    <origin xyz="0.117 0.0 0.0599999999999999" rpy="0.0 0.0 0.0"/>
  </joint>
  <joint name="upperarm_roll_joint" type="continuous">
    <dynamics damping="5.0"/>
    <limit effort="76.94" velocity="1.571"/>
    <parent link="shoulder_lift_link"/>
    <child link="upperarm_roll_link"/>
    <axis xyz="1. 0. 0."/>
    <origin xyz="0.219 0.0 0.0" rpy="0.0 0.0 0.0"/>
  </joint>
  <joint name="elbow_flex_joint" type="revolute">
    <dynamics damping="1.0"/>
    <limit effort="66.18" velocity="1.521" lower="-2.251" upper="2.251"/>
    <parent link="upperarm_roll_link"/>
    <child link="elbow_flex_link"/>
    <axis xyz="0. 1. 0."/>
    <origin xyz="0.133 0.0 0.0" rpy="0.0 0.0 0.0"/>
  </joint>
  <joint name="forearm_roll_joint" type="continuous">
    <dynamics damping="5.0"/>
    <limit effort="29.35" velocity="1.571"/>
    <parent link="elbow_flex_link"/>
    <child link="forearm_roll_link"/>
    <axis xyz="1. 0. 0."/>
    <origin xyz="0.197 0.0 0.0" rpy="0.0 0.0 0.0"/>
  </joint>
  <joint name="wrist_flex_joint" type="revolute">
    <dynamics damping="1.0"/>
    <limit effort="25.7" velocity="2.268" lower="-2.16" upper="2.16"/>
    <parent link="forearm_roll_link"/>
    <child link="wrist_flex_link"/>
    <axis xyz="0. 1. 0."/>
    <origin xyz="0.1245 0.0 0.0" rpy="0.0 0.0 0.0"/>
  </joint>
  <joint name="wrist_roll_joint" type="continuous">
    <dynamics damping="5.0"/>
    <limit effort="7.36" velocity="2.268"/>
    <parent link="wrist_flex_link"/>
    <child link="wrist_roll_link"/>
    <axis xyz="1. 0. 0."/>
    <origin xyz="0.1385 0.0 0.0" rpy="0.0 0.0 0.0"/>
  </joint>
  <joint name="gripper_axis" type="fixed">
    <parent link="wrist_roll_link"/>
    <child link="gripper_link"/>
    <axis xyz="0. 1. 0."/>
    <origin xyz="0.16645 0.0 0.0" rpy="0.0 0.0 0.0"/>
  </joint>
  <joint name="r_gripper_finger_joint" type="prismatic">
    <dynamics damping="100.0"/>
    <limit effort="60.0" velocity="0.05" lower="0.0" upper="0.05"/>
    <parent link="gripper_link"/>
    <child link="r_gripper_finger_link"/>
    <axis xyz="0. 1. 0."/>
    <origin xyz="0.0 0.015425 0.0" rpy="0.0 0.0 0.0"/>
  </joint>
  <joint name="l_gripper_finger_joint" type="prismatic">
    <dynamics damping="100.0"/>
    <limit effort="60.0" velocity="0.05" lower="0.0" upper="0.05"/>
    <parent link="gripper_link"/>
    <child link="l_gripper_finger_link"/>
    <axis xyz=" 0. -1.  0."/>
    <origin xyz="0.0 0.0 0.0" rpy="0.0 0.0 0.0"/>
  </joint>
  <joint name="bellows_joint" type="fixed">
    <parent link="base_link"/>
    <child link="bellows_link"/>
    <axis xyz="1. 0. 0."/>
    <origin xyz="-0.1 0.0 0.5" rpy="0.0 0.0 0.0"/>
  </joint>
  <joint name="bellows_joint2" type="fixed">
    <parent link="torso_lift_link"/>
    <child link="bellows_link2"/>
    <axis xyz="1. 0. 0."/>
    <origin xyz="0.0 0.0 0.0" rpy="0.0 0.0 0.0"/>
  </joint>
  <joint name="estop_joint" type="fixed">
    <parent link="base_link"/>
    <child link="estop_link"/>
    <axis xyz="1. 0. 0."/>
    <origin xyz="-0.12465 0.23892 0.31127" rpy="1.5708 0.0 0.0"/>
  </joint>
  <joint name="laser_joint" type="fixed">
    <parent link="base_link"/>
    <child link="laser_link"/>
    <axis xyz="1. 0. 0."/>
    <origin xyz="0.235 0.0 0.2878" rpy="-3.1415926535895866 0.0 0.0"/>
  </joint>
  <joint name="torso_fixed_joint" type="fixed">
    <parent link="base_link"/>
    <child link="torso_fixed_link"/>
    <axis xyz="0. 1. 0."/>
    <origin xyz="-0.086875 0.0 0.377425" rpy="-6.12303176911189e-17 0.0 0.0"/>
  </joint>
  <joint name="head_camera_joint" type="fixed">
    <parent link="head_tilt_link"/>
    <child link="head_camera_link"/>
    <axis xyz="1. 0. 0."/>
    <origin xyz="0.055 0.0 0.0225" rpy="0.0 0.0 0.0"/>
  </joint>
  <joint name="head_camera_rgb_joint" type="fixed">
    <parent link="head_camera_link"/>
    <child link="head_camera_rgb_frame"/>
    <axis xyz="1. 0. 0."/>
    <origin xyz="0.0 0.02 0.0" rpy="0.0 0.0 0.0"/>
  </joint>
  <joint name="head_camera_rgb_optical_joint" type="fixed">
    <parent link="head_camera_rgb_frame"/>
    <child link="head_camera_rgb_optical_frame"/>
    <axis xyz="1. 0. 0."/>
    <origin xyz="0.0 0.0 0.0" rpy="-1.57079632679 0.0 -1.57079632679"/>
  </joint>
  <joint name="head_camera_depth_joint" type="fixed">
    <parent link="head_camera_link"/>
    <child link="head_camera_depth_frame"/>
    <axis xyz="1. 0. 0."/>
    <origin xyz="0.0 0.045 0.0" rpy="0.0 0.0 0.0"/>
  </joint>
  <joint name="head_camera_depth_optical_joint" type="fixed">
    <parent link="head_camera_depth_frame"/>
    <child link="head_camera_depth_optical_frame"/>
    <axis xyz="1. 0. 0."/>
    <origin xyz="0.0 0.0 0.0" rpy="-1.57079632679 0.0 -1.57079632679"/>
  </joint>
  <joint name="articulated_agent_arm_joint" type="fixed">
    <parent link="gripper_link"/>
    <child link="articulated_agent_arm"/>
    <axis xyz="1. 0. 0."/>
    <origin xyz="-0.10000000149011612 4.371139006309477e-09 1.9106855710438234e-16" rpy="0.0 -0.0 0.0"/>
  </joint>
  <material name="mat0">
    <color rgba="0.356 0.361 0.376 1.   "/>
  </material>
  <material name="mat1">
    <color rgba="0.086 0.506 0.767 1.   "/>
  </material>
  <material name="mat2">
    <color rgba="0.086 0.506 0.767 1.   "/>
  </material>
  <material name="math3">
    <color rgba="1. 1. 1. 1."/>
  </material>
  <material name="math4">
    <color rgba="0.356 0.361 0.376 1.   "/>
  </material>
  <material name="5">
    <color rgba="0.086 0.506 0.767 1.   "/>
  </material>
  <material name="6">
    <color rgba="1. 1. 1. 1."/>
  </material>
  <material name="7">
    <color rgba="0.086 0.506 0.767 1.   "/>
  </material>
  <material name="8">
    <color rgba="1. 1. 1. 1."/>
  </material>
  <material name="9">
    <color rgba="0.086 0.506 0.767 1.   "/>
  </material>
  <material name="10">
    <color rgba="1. 1. 1. 1."/>
  </material>
  <material name="11">
    <color rgba="0.086 0.506 0.767 1.   "/>
  </material>
  <material name="12">
    <color rgba="1. 1. 1. 1."/>
  </material>
  <material name="13">
    <color rgba="0.356 0.361 0.376 1.   "/>
  </material>
  <material name="14">
    <color rgba="0.356 0.361 0.376 1.   "/>
  </material>
  <material name="15">
    <color rgba="0. 0. 0. 1."/>
  </material>
  <material name="16">
    <color rgba="0. 0. 0. 1."/>
  </material>
  <material name="17">
    <color rgba="0.8 0.  0.  1. "/>
  </material>
  <material name="18">
    <color rgba="0.79215686 0.81960784 0.93333333 1.        "/>
  </material>
  <material name="">
    <color rgba="0.086 0.506 0.767 1.   "/>
  </material>
</robot>
